[33mWARNING[0m:  [07-04-2024 14:37:33] chroma_server_nofile is set to 65535, but this is less than current soft limit of 1048576. chroma_server_nofile will not be set.
[32mINFO[0m:     [07-04-2024 14:37:33] Anonymized telemetry enabled. See                     https://docs.trychroma.com/telemetry for more information.
[36mDEBUG[0m:    [07-04-2024 14:37:33] Starting component System
[36mDEBUG[0m:    [07-04-2024 14:37:33] Starting component OpenTelemetryClient
[36mDEBUG[0m:    [07-04-2024 14:37:33] Starting component SimpleAssignmentPolicy
[36mDEBUG[0m:    [07-04-2024 14:37:33] Starting component SqliteDB
[36mDEBUG[0m:    [07-04-2024 14:37:33] Starting component QuotaEnforcer
[36mDEBUG[0m:    [07-04-2024 14:37:33] Starting component Posthog
[36mDEBUG[0m:    [07-04-2024 14:37:33] Starting component LocalSegmentManager
[36mDEBUG[0m:    [07-04-2024 14:37:33] Starting component SegmentAPI
[32mINFO[0m:     [07-04-2024 14:37:33] Started server process [[36m18621[0m]
[32mINFO[0m:     [07-04-2024 14:37:33] Waiting for application startup.
[32mINFO[0m:     [07-04-2024 14:37:33] Application startup complete.
[32mINFO[0m:     [07-04-2024 14:37:33] Uvicorn running on [1mhttp://localhost:8000[0m (Press CTRL+C to quit)
[32mINFO[0m:     [07-04-2024 14:39:44] 127.0.0.1:39834 - "GET / HTTP/1.1" 404
[32mINFO[0m:     [07-04-2024 14:39:45] 127.0.0.1:39834 - "GET /favicon.ico HTTP/1.1" 404
[32mINFO[0m:     [07-04-2024 14:40:08] 127.0.0.1:49714 - "POST /api/v1/collections?tenant=default_tenant&database=default_database HTTP/1.1" 200
[36mDEBUG[0m:    [07-04-2024 14:40:08] Starting component PersistentLocalHnswSegment
[32mINFO[0m:     [07-04-2024 14:40:09] 127.0.0.1:49714 - "POST /api/v1/collections/5d98ccf9-8f68-4ca9-bcf1-4d7d95e1eb20/add HTTP/1.1" 201
[32mINFO[0m:     [07-04-2024 14:40:09] 127.0.0.1:49714 - "POST /api/v1/collections/5d98ccf9-8f68-4ca9-bcf1-4d7d95e1eb20/add HTTP/1.1" 201
[32mINFO[0m:     [07-04-2024 14:40:09] 127.0.0.1:49714 - "POST /api/v1/collections/5d98ccf9-8f68-4ca9-bcf1-4d7d95e1eb20/add HTTP/1.1" 201
[32mINFO[0m:     [07-04-2024 14:40:09] 127.0.0.1:49714 - "POST /api/v1/collections/5d98ccf9-8f68-4ca9-bcf1-4d7d95e1eb20/add HTTP/1.1" 201
[32mINFO[0m:     [07-04-2024 14:40:09] 127.0.0.1:49714 - "POST /api/v1/collections/5d98ccf9-8f68-4ca9-bcf1-4d7d95e1eb20/add HTTP/1.1" 201
[32mINFO[0m:     [07-04-2024 14:40:09] 127.0.0.1:49714 - "POST /api/v1/collections/5d98ccf9-8f68-4ca9-bcf1-4d7d95e1eb20/add HTTP/1.1" 201
[32mINFO[0m:     [07-04-2024 14:40:09] 127.0.0.1:49714 - "POST /api/v1/collections/5d98ccf9-8f68-4ca9-bcf1-4d7d95e1eb20/add HTTP/1.1" 201
[32mINFO[0m:     [07-04-2024 14:40:09] 127.0.0.1:49714 - "POST /api/v1/collections/5d98ccf9-8f68-4ca9-bcf1-4d7d95e1eb20/add HTTP/1.1" 201
[32mINFO[0m:     [07-04-2024 14:40:09] 127.0.0.1:49714 - "POST /api/v1/collections/5d98ccf9-8f68-4ca9-bcf1-4d7d95e1eb20/add HTTP/1.1" 201
[32mINFO[0m:     [07-04-2024 14:40:09] 127.0.0.1:49714 - "POST /api/v1/collections/5d98ccf9-8f68-4ca9-bcf1-4d7d95e1eb20/add HTTP/1.1" 201
[32mINFO[0m:     [07-04-2024 14:40:09] 127.0.0.1:49714 - "POST /api/v1/collections/5d98ccf9-8f68-4ca9-bcf1-4d7d95e1eb20/add HTTP/1.1" 201
[32mINFO[0m:     [07-04-2024 14:40:09] 127.0.0.1:49714 - "POST /api/v1/collections/5d98ccf9-8f68-4ca9-bcf1-4d7d95e1eb20/add HTTP/1.1" 201
[32mINFO[0m:     [07-04-2024 14:40:09] 127.0.0.1:49714 - "POST /api/v1/collections/5d98ccf9-8f68-4ca9-bcf1-4d7d95e1eb20/add HTTP/1.1" 201
[32mINFO[0m:     [07-04-2024 14:40:09] 127.0.0.1:49714 - "POST /api/v1/collections/5d98ccf9-8f68-4ca9-bcf1-4d7d95e1eb20/add HTTP/1.1" 201
[32mINFO[0m:     [07-04-2024 14:40:09] 127.0.0.1:49714 - "POST /api/v1/collections/5d98ccf9-8f68-4ca9-bcf1-4d7d95e1eb20/add HTTP/1.1" 201
[32mINFO[0m:     [07-04-2024 14:40:09] 127.0.0.1:49714 - "POST /api/v1/collections/5d98ccf9-8f68-4ca9-bcf1-4d7d95e1eb20/add HTTP/1.1" 201
[32mINFO[0m:     [07-04-2024 14:40:09] 127.0.0.1:49714 - "POST /api/v1/collections/5d98ccf9-8f68-4ca9-bcf1-4d7d95e1eb20/add HTTP/1.1" 201
[32mINFO[0m:     [07-04-2024 14:40:09] 127.0.0.1:49714 - "POST /api/v1/collections/5d98ccf9-8f68-4ca9-bcf1-4d7d95e1eb20/add HTTP/1.1" 201
[32mINFO[0m:     [07-04-2024 14:40:09] 127.0.0.1:49714 - "POST /api/v1/collections/5d98ccf9-8f68-4ca9-bcf1-4d7d95e1eb20/add HTTP/1.1" 201
[32mINFO[0m:     [07-04-2024 14:40:09] 127.0.0.1:49714 - "POST /api/v1/collections/5d98ccf9-8f68-4ca9-bcf1-4d7d95e1eb20/add HTTP/1.1" 201
[32mINFO[0m:     [07-04-2024 14:40:09] 127.0.0.1:49714 - "POST /api/v1/collections/5d98ccf9-8f68-4ca9-bcf1-4d7d95e1eb20/query HTTP/1.1" 200
[32mINFO[0m:     [07-04-2024 14:40:43] Backing off send_request(...) for 0.6s (requests.exceptions.ReadTimeout: HTTPSConnectionPool(host='us-api.i.posthog.com', port=443): Read timed out. (read timeout=15))
[32mINFO[0m:     [07-04-2024 14:41:02] Backing off send_request(...) for 1.4s (requests.exceptions.ReadTimeout: HTTPSConnectionPool(host='us-api.i.posthog.com', port=443): Read timed out. (read timeout=15))
[31mERROR[0m:    [07-04-2024 14:41:24] Collection test-from-js already exists
Traceback (most recent call last):
  File "/home/omar/.local/lib/python3.10/site-packages/anyio/streams/memory.py", line 98, in receive
    return self.receive_nowait()
  File "/home/omar/.local/lib/python3.10/site-packages/anyio/streams/memory.py", line 93, in receive_nowait
    raise WouldBlock
anyio.WouldBlock

During handling of the above exception, another exception occurred:

Traceback (most recent call last):
  File "/home/omar/.local/lib/python3.10/site-packages/starlette/middleware/base.py", line 159, in call_next
    message = await recv_stream.receive()
  File "/home/omar/.local/lib/python3.10/site-packages/anyio/streams/memory.py", line 118, in receive
    raise EndOfStream
anyio.EndOfStream

During handling of the above exception, another exception occurred:

Traceback (most recent call last):
  File "/home/omar/.local/lib/python3.10/site-packages/chromadb/server/fastapi/__init__.py", line 82, in catch_exceptions_middleware
    return await call_next(request)
  File "/home/omar/.local/lib/python3.10/site-packages/starlette/middleware/base.py", line 165, in call_next
    raise app_exc
  File "/home/omar/.local/lib/python3.10/site-packages/starlette/middleware/base.py", line 151, in coro
    await self.app(scope, receive_or_disconnect, send_no_error)
  File "/home/omar/.local/lib/python3.10/site-packages/starlette/middleware/base.py", line 191, in __call__
    response = await self.dispatch_func(request, call_next)
  File "/home/omar/.local/lib/python3.10/site-packages/chromadb/server/fastapi/__init__.py", line 96, in check_http_version_middleware
    return await call_next(request)
  File "/home/omar/.local/lib/python3.10/site-packages/starlette/middleware/base.py", line 165, in call_next
    raise app_exc
  File "/home/omar/.local/lib/python3.10/site-packages/starlette/middleware/base.py", line 151, in coro
    await self.app(scope, receive_or_disconnect, send_no_error)
  File "/home/omar/.local/lib/python3.10/site-packages/starlette/middleware/exceptions.py", line 65, in __call__
    await wrap_app_handling_exceptions(self.app, conn)(scope, receive, send)
  File "/home/omar/.local/lib/python3.10/site-packages/starlette/_exception_handler.py", line 64, in wrapped_app
    raise exc
  File "/home/omar/.local/lib/python3.10/site-packages/starlette/_exception_handler.py", line 53, in wrapped_app
    await app(scope, receive, sender)
  File "/home/omar/.local/lib/python3.10/site-packages/starlette/routing.py", line 756, in __call__
    await self.middleware_stack(scope, receive, send)
  File "/home/omar/.local/lib/python3.10/site-packages/starlette/routing.py", line 776, in app
    await route.handle(scope, receive, send)
  File "/home/omar/.local/lib/python3.10/site-packages/starlette/routing.py", line 297, in handle
    await self.app(scope, receive, send)
  File "/home/omar/.local/lib/python3.10/site-packages/starlette/routing.py", line 77, in app
    await wrap_app_handling_exceptions(app, request)(scope, receive, send)
  File "/home/omar/.local/lib/python3.10/site-packages/starlette/_exception_handler.py", line 64, in wrapped_app
    raise exc
  File "/home/omar/.local/lib/python3.10/site-packages/starlette/_exception_handler.py", line 53, in wrapped_app
    await app(scope, receive, sender)
  File "/home/omar/.local/lib/python3.10/site-packages/starlette/routing.py", line 72, in app
    response = await func(request)
  File "/home/omar/.local/lib/python3.10/site-packages/fastapi/routing.py", line 278, in app
    raw_response = await run_endpoint_function(
  File "/home/omar/.local/lib/python3.10/site-packages/fastapi/routing.py", line 193, in run_endpoint_function
    return await run_in_threadpool(dependant.call, **values)
  File "/home/omar/.local/lib/python3.10/site-packages/starlette/concurrency.py", line 42, in run_in_threadpool
    return await anyio.to_thread.run_sync(func, *args)
  File "/home/omar/.local/lib/python3.10/site-packages/anyio/to_thread.py", line 33, in run_sync
    return await get_asynclib().run_sync_in_worker_thread(
  File "/home/omar/.local/lib/python3.10/site-packages/anyio/_backends/_asyncio.py", line 877, in run_sync_in_worker_thread
    return await future
  File "/home/omar/.local/lib/python3.10/site-packages/anyio/_backends/_asyncio.py", line 807, in run
    result = context.run(func, *args)
  File "/home/omar/.local/lib/python3.10/site-packages/chromadb/telemetry/opentelemetry/__init__.py", line 127, in wrapper
    return f(*args, **kwargs)
  File "/home/omar/.local/lib/python3.10/site-packages/chromadb/auth/fastapi.py", line 241, in wrapped
    return f(*args, **kwargs)
  File "/home/omar/.local/lib/python3.10/site-packages/chromadb/server/fastapi/__init__.py", line 415, in create_collection
    return self._api.create_collection(
  File "/home/omar/.local/lib/python3.10/site-packages/chromadb/telemetry/opentelemetry/__init__.py", line 127, in wrapper
    return f(*args, **kwargs)
  File "/home/omar/.local/lib/python3.10/site-packages/chromadb/api/segment.py", line 167, in create_collection
    coll, created = self._sysdb.create_collection(
  File "/home/omar/.local/lib/python3.10/site-packages/chromadb/telemetry/opentelemetry/__init__.py", line 127, in wrapper
    return f(*args, **kwargs)
  File "/home/omar/.local/lib/python3.10/site-packages/chromadb/db/mixins/sysdb.py", line 225, in create_collection
    raise UniqueConstraintError(f"Collection {name} already exists")
chromadb.db.base.UniqueConstraintError: Collection test-from-js already exists
[32mINFO[0m:     [07-04-2024 14:41:24] 127.0.0.1:40704 - "POST /api/v1/collections?tenant=default_tenant&database=default_database HTTP/1.1" 500
[31mERROR[0m:    [07-04-2024 14:41:28] Collection test-from-js already exists
Traceback (most recent call last):
  File "/home/omar/.local/lib/python3.10/site-packages/anyio/streams/memory.py", line 98, in receive
    return self.receive_nowait()
  File "/home/omar/.local/lib/python3.10/site-packages/anyio/streams/memory.py", line 93, in receive_nowait
    raise WouldBlock
anyio.WouldBlock

During handling of the above exception, another exception occurred:

Traceback (most recent call last):
  File "/home/omar/.local/lib/python3.10/site-packages/starlette/middleware/base.py", line 159, in call_next
    message = await recv_stream.receive()
  File "/home/omar/.local/lib/python3.10/site-packages/anyio/streams/memory.py", line 118, in receive
    raise EndOfStream
anyio.EndOfStream

During handling of the above exception, another exception occurred:

Traceback (most recent call last):
  File "/home/omar/.local/lib/python3.10/site-packages/chromadb/server/fastapi/__init__.py", line 82, in catch_exceptions_middleware
    return await call_next(request)
  File "/home/omar/.local/lib/python3.10/site-packages/starlette/middleware/base.py", line 165, in call_next
    raise app_exc
  File "/home/omar/.local/lib/python3.10/site-packages/starlette/middleware/base.py", line 151, in coro
    await self.app(scope, receive_or_disconnect, send_no_error)
  File "/home/omar/.local/lib/python3.10/site-packages/starlette/middleware/base.py", line 191, in __call__
    response = await self.dispatch_func(request, call_next)
  File "/home/omar/.local/lib/python3.10/site-packages/chromadb/server/fastapi/__init__.py", line 96, in check_http_version_middleware
    return await call_next(request)
  File "/home/omar/.local/lib/python3.10/site-packages/starlette/middleware/base.py", line 165, in call_next
    raise app_exc
  File "/home/omar/.local/lib/python3.10/site-packages/starlette/middleware/base.py", line 151, in coro
    await self.app(scope, receive_or_disconnect, send_no_error)
  File "/home/omar/.local/lib/python3.10/site-packages/starlette/middleware/exceptions.py", line 65, in __call__
    await wrap_app_handling_exceptions(self.app, conn)(scope, receive, send)
  File "/home/omar/.local/lib/python3.10/site-packages/starlette/_exception_handler.py", line 64, in wrapped_app
    raise exc
  File "/home/omar/.local/lib/python3.10/site-packages/starlette/_exception_handler.py", line 53, in wrapped_app
    await app(scope, receive, sender)
  File "/home/omar/.local/lib/python3.10/site-packages/starlette/routing.py", line 756, in __call__
    await self.middleware_stack(scope, receive, send)
  File "/home/omar/.local/lib/python3.10/site-packages/starlette/routing.py", line 776, in app
    await route.handle(scope, receive, send)
  File "/home/omar/.local/lib/python3.10/site-packages/starlette/routing.py", line 297, in handle
    await self.app(scope, receive, send)
  File "/home/omar/.local/lib/python3.10/site-packages/starlette/routing.py", line 77, in app
    await wrap_app_handling_exceptions(app, request)(scope, receive, send)
  File "/home/omar/.local/lib/python3.10/site-packages/starlette/_exception_handler.py", line 64, in wrapped_app
    raise exc
  File "/home/omar/.local/lib/python3.10/site-packages/starlette/_exception_handler.py", line 53, in wrapped_app
    await app(scope, receive, sender)
  File "/home/omar/.local/lib/python3.10/site-packages/starlette/routing.py", line 72, in app
    response = await func(request)
  File "/home/omar/.local/lib/python3.10/site-packages/fastapi/routing.py", line 278, in app
    raw_response = await run_endpoint_function(
  File "/home/omar/.local/lib/python3.10/site-packages/fastapi/routing.py", line 193, in run_endpoint_function
    return await run_in_threadpool(dependant.call, **values)
  File "/home/omar/.local/lib/python3.10/site-packages/starlette/concurrency.py", line 42, in run_in_threadpool
    return await anyio.to_thread.run_sync(func, *args)
  File "/home/omar/.local/lib/python3.10/site-packages/anyio/to_thread.py", line 33, in run_sync
    return await get_asynclib().run_sync_in_worker_thread(
  File "/home/omar/.local/lib/python3.10/site-packages/anyio/_backends/_asyncio.py", line 877, in run_sync_in_worker_thread
    return await future
  File "/home/omar/.local/lib/python3.10/site-packages/anyio/_backends/_asyncio.py", line 807, in run
    result = context.run(func, *args)
  File "/home/omar/.local/lib/python3.10/site-packages/chromadb/telemetry/opentelemetry/__init__.py", line 127, in wrapper
    return f(*args, **kwargs)
  File "/home/omar/.local/lib/python3.10/site-packages/chromadb/auth/fastapi.py", line 241, in wrapped
    return f(*args, **kwargs)
  File "/home/omar/.local/lib/python3.10/site-packages/chromadb/server/fastapi/__init__.py", line 415, in create_collection
    return self._api.create_collection(
  File "/home/omar/.local/lib/python3.10/site-packages/chromadb/telemetry/opentelemetry/__init__.py", line 127, in wrapper
    return f(*args, **kwargs)
  File "/home/omar/.local/lib/python3.10/site-packages/chromadb/api/segment.py", line 167, in create_collection
    coll, created = self._sysdb.create_collection(
  File "/home/omar/.local/lib/python3.10/site-packages/chromadb/telemetry/opentelemetry/__init__.py", line 127, in wrapper
    return f(*args, **kwargs)
  File "/home/omar/.local/lib/python3.10/site-packages/chromadb/db/mixins/sysdb.py", line 225, in create_collection
    raise UniqueConstraintError(f"Collection {name} already exists")
chromadb.db.base.UniqueConstraintError: Collection test-from-js already exists
[32mINFO[0m:     [07-04-2024 14:41:28] 127.0.0.1:44802 - "POST /api/v1/collections?tenant=default_tenant&database=default_database HTTP/1.1" 500
[31mERROR[0m:    [07-04-2024 14:42:18] Collection test-from-js already exists
Traceback (most recent call last):
  File "/home/omar/.local/lib/python3.10/site-packages/anyio/streams/memory.py", line 98, in receive
    return self.receive_nowait()
  File "/home/omar/.local/lib/python3.10/site-packages/anyio/streams/memory.py", line 93, in receive_nowait
    raise WouldBlock
anyio.WouldBlock

During handling of the above exception, another exception occurred:

Traceback (most recent call last):
  File "/home/omar/.local/lib/python3.10/site-packages/starlette/middleware/base.py", line 159, in call_next
    message = await recv_stream.receive()
  File "/home/omar/.local/lib/python3.10/site-packages/anyio/streams/memory.py", line 118, in receive
    raise EndOfStream
anyio.EndOfStream

During handling of the above exception, another exception occurred:

Traceback (most recent call last):
  File "/home/omar/.local/lib/python3.10/site-packages/chromadb/server/fastapi/__init__.py", line 82, in catch_exceptions_middleware
    return await call_next(request)
  File "/home/omar/.local/lib/python3.10/site-packages/starlette/middleware/base.py", line 165, in call_next
    raise app_exc
  File "/home/omar/.local/lib/python3.10/site-packages/starlette/middleware/base.py", line 151, in coro
    await self.app(scope, receive_or_disconnect, send_no_error)
  File "/home/omar/.local/lib/python3.10/site-packages/starlette/middleware/base.py", line 191, in __call__
    response = await self.dispatch_func(request, call_next)
  File "/home/omar/.local/lib/python3.10/site-packages/chromadb/server/fastapi/__init__.py", line 96, in check_http_version_middleware
    return await call_next(request)
  File "/home/omar/.local/lib/python3.10/site-packages/starlette/middleware/base.py", line 165, in call_next
    raise app_exc
  File "/home/omar/.local/lib/python3.10/site-packages/starlette/middleware/base.py", line 151, in coro
    await self.app(scope, receive_or_disconnect, send_no_error)
  File "/home/omar/.local/lib/python3.10/site-packages/starlette/middleware/exceptions.py", line 65, in __call__
    await wrap_app_handling_exceptions(self.app, conn)(scope, receive, send)
  File "/home/omar/.local/lib/python3.10/site-packages/starlette/_exception_handler.py", line 64, in wrapped_app
    raise exc
  File "/home/omar/.local/lib/python3.10/site-packages/starlette/_exception_handler.py", line 53, in wrapped_app
    await app(scope, receive, sender)
  File "/home/omar/.local/lib/python3.10/site-packages/starlette/routing.py", line 756, in __call__
    await self.middleware_stack(scope, receive, send)
  File "/home/omar/.local/lib/python3.10/site-packages/starlette/routing.py", line 776, in app
    await route.handle(scope, receive, send)
  File "/home/omar/.local/lib/python3.10/site-packages/starlette/routing.py", line 297, in handle
    await self.app(scope, receive, send)
  File "/home/omar/.local/lib/python3.10/site-packages/starlette/routing.py", line 77, in app
    await wrap_app_handling_exceptions(app, request)(scope, receive, send)
  File "/home/omar/.local/lib/python3.10/site-packages/starlette/_exception_handler.py", line 64, in wrapped_app
    raise exc
  File "/home/omar/.local/lib/python3.10/site-packages/starlette/_exception_handler.py", line 53, in wrapped_app
    await app(scope, receive, sender)
  File "/home/omar/.local/lib/python3.10/site-packages/starlette/routing.py", line 72, in app
    response = await func(request)
  File "/home/omar/.local/lib/python3.10/site-packages/fastapi/routing.py", line 278, in app
    raw_response = await run_endpoint_function(
  File "/home/omar/.local/lib/python3.10/site-packages/fastapi/routing.py", line 193, in run_endpoint_function
    return await run_in_threadpool(dependant.call, **values)
  File "/home/omar/.local/lib/python3.10/site-packages/starlette/concurrency.py", line 42, in run_in_threadpool
    return await anyio.to_thread.run_sync(func, *args)
  File "/home/omar/.local/lib/python3.10/site-packages/anyio/to_thread.py", line 33, in run_sync
    return await get_asynclib().run_sync_in_worker_thread(
  File "/home/omar/.local/lib/python3.10/site-packages/anyio/_backends/_asyncio.py", line 877, in run_sync_in_worker_thread
    return await future
  File "/home/omar/.local/lib/python3.10/site-packages/anyio/_backends/_asyncio.py", line 807, in run
    result = context.run(func, *args)
  File "/home/omar/.local/lib/python3.10/site-packages/chromadb/telemetry/opentelemetry/__init__.py", line 127, in wrapper
    return f(*args, **kwargs)
  File "/home/omar/.local/lib/python3.10/site-packages/chromadb/auth/fastapi.py", line 241, in wrapped
    return f(*args, **kwargs)
  File "/home/omar/.local/lib/python3.10/site-packages/chromadb/server/fastapi/__init__.py", line 415, in create_collection
    return self._api.create_collection(
  File "/home/omar/.local/lib/python3.10/site-packages/chromadb/telemetry/opentelemetry/__init__.py", line 127, in wrapper
    return f(*args, **kwargs)
  File "/home/omar/.local/lib/python3.10/site-packages/chromadb/api/segment.py", line 167, in create_collection
    coll, created = self._sysdb.create_collection(
  File "/home/omar/.local/lib/python3.10/site-packages/chromadb/telemetry/opentelemetry/__init__.py", line 127, in wrapper
    return f(*args, **kwargs)
  File "/home/omar/.local/lib/python3.10/site-packages/chromadb/db/mixins/sysdb.py", line 225, in create_collection
    raise UniqueConstraintError(f"Collection {name} already exists")
chromadb.db.base.UniqueConstraintError: Collection test-from-js already exists
[32mINFO[0m:     [07-04-2024 14:42:18] 127.0.0.1:34800 - "POST /api/v1/collections?tenant=default_tenant&database=default_database HTTP/1.1" 500
[31mERROR[0m:    [07-04-2024 14:44:43] Collection test-from-js already exists
Traceback (most recent call last):
  File "/home/omar/.local/lib/python3.10/site-packages/anyio/streams/memory.py", line 98, in receive
    return self.receive_nowait()
  File "/home/omar/.local/lib/python3.10/site-packages/anyio/streams/memory.py", line 93, in receive_nowait
    raise WouldBlock
anyio.WouldBlock

During handling of the above exception, another exception occurred:

Traceback (most recent call last):
  File "/home/omar/.local/lib/python3.10/site-packages/starlette/middleware/base.py", line 159, in call_next
    message = await recv_stream.receive()
  File "/home/omar/.local/lib/python3.10/site-packages/anyio/streams/memory.py", line 118, in receive
    raise EndOfStream
anyio.EndOfStream

During handling of the above exception, another exception occurred:

Traceback (most recent call last):
  File "/home/omar/.local/lib/python3.10/site-packages/chromadb/server/fastapi/__init__.py", line 82, in catch_exceptions_middleware
    return await call_next(request)
  File "/home/omar/.local/lib/python3.10/site-packages/starlette/middleware/base.py", line 165, in call_next
    raise app_exc
  File "/home/omar/.local/lib/python3.10/site-packages/starlette/middleware/base.py", line 151, in coro
    await self.app(scope, receive_or_disconnect, send_no_error)
  File "/home/omar/.local/lib/python3.10/site-packages/starlette/middleware/base.py", line 191, in __call__
    response = await self.dispatch_func(request, call_next)
  File "/home/omar/.local/lib/python3.10/site-packages/chromadb/server/fastapi/__init__.py", line 96, in check_http_version_middleware
    return await call_next(request)
  File "/home/omar/.local/lib/python3.10/site-packages/starlette/middleware/base.py", line 165, in call_next
    raise app_exc
  File "/home/omar/.local/lib/python3.10/site-packages/starlette/middleware/base.py", line 151, in coro
    await self.app(scope, receive_or_disconnect, send_no_error)
  File "/home/omar/.local/lib/python3.10/site-packages/starlette/middleware/exceptions.py", line 65, in __call__
    await wrap_app_handling_exceptions(self.app, conn)(scope, receive, send)
  File "/home/omar/.local/lib/python3.10/site-packages/starlette/_exception_handler.py", line 64, in wrapped_app
    raise exc
  File "/home/omar/.local/lib/python3.10/site-packages/starlette/_exception_handler.py", line 53, in wrapped_app
    await app(scope, receive, sender)
  File "/home/omar/.local/lib/python3.10/site-packages/starlette/routing.py", line 756, in __call__
    await self.middleware_stack(scope, receive, send)
  File "/home/omar/.local/lib/python3.10/site-packages/starlette/routing.py", line 776, in app
    await route.handle(scope, receive, send)
  File "/home/omar/.local/lib/python3.10/site-packages/starlette/routing.py", line 297, in handle
    await self.app(scope, receive, send)
  File "/home/omar/.local/lib/python3.10/site-packages/starlette/routing.py", line 77, in app
    await wrap_app_handling_exceptions(app, request)(scope, receive, send)
  File "/home/omar/.local/lib/python3.10/site-packages/starlette/_exception_handler.py", line 64, in wrapped_app
    raise exc
  File "/home/omar/.local/lib/python3.10/site-packages/starlette/_exception_handler.py", line 53, in wrapped_app
    await app(scope, receive, sender)
  File "/home/omar/.local/lib/python3.10/site-packages/starlette/routing.py", line 72, in app
    response = await func(request)
  File "/home/omar/.local/lib/python3.10/site-packages/fastapi/routing.py", line 278, in app
    raw_response = await run_endpoint_function(
  File "/home/omar/.local/lib/python3.10/site-packages/fastapi/routing.py", line 193, in run_endpoint_function
    return await run_in_threadpool(dependant.call, **values)
  File "/home/omar/.local/lib/python3.10/site-packages/starlette/concurrency.py", line 42, in run_in_threadpool
    return await anyio.to_thread.run_sync(func, *args)
  File "/home/omar/.local/lib/python3.10/site-packages/anyio/to_thread.py", line 33, in run_sync
    return await get_asynclib().run_sync_in_worker_thread(
  File "/home/omar/.local/lib/python3.10/site-packages/anyio/_backends/_asyncio.py", line 877, in run_sync_in_worker_thread
    return await future
  File "/home/omar/.local/lib/python3.10/site-packages/anyio/_backends/_asyncio.py", line 807, in run
    result = context.run(func, *args)
  File "/home/omar/.local/lib/python3.10/site-packages/chromadb/telemetry/opentelemetry/__init__.py", line 127, in wrapper
    return f(*args, **kwargs)
  File "/home/omar/.local/lib/python3.10/site-packages/chromadb/auth/fastapi.py", line 241, in wrapped
    return f(*args, **kwargs)
  File "/home/omar/.local/lib/python3.10/site-packages/chromadb/server/fastapi/__init__.py", line 415, in create_collection
    return self._api.create_collection(
  File "/home/omar/.local/lib/python3.10/site-packages/chromadb/telemetry/opentelemetry/__init__.py", line 127, in wrapper
    return f(*args, **kwargs)
  File "/home/omar/.local/lib/python3.10/site-packages/chromadb/api/segment.py", line 167, in create_collection
    coll, created = self._sysdb.create_collection(
  File "/home/omar/.local/lib/python3.10/site-packages/chromadb/telemetry/opentelemetry/__init__.py", line 127, in wrapper
    return f(*args, **kwargs)
  File "/home/omar/.local/lib/python3.10/site-packages/chromadb/db/mixins/sysdb.py", line 225, in create_collection
    raise UniqueConstraintError(f"Collection {name} already exists")
chromadb.db.base.UniqueConstraintError: Collection test-from-js already exists
[32mINFO[0m:     [07-04-2024 14:44:43] 127.0.0.1:44076 - "POST /api/v1/collections?tenant=default_tenant&database=default_database HTTP/1.1" 500
[31mERROR[0m:    [07-04-2024 14:47:02] Collection test-from-js already exists
Traceback (most recent call last):
  File "/home/omar/.local/lib/python3.10/site-packages/anyio/streams/memory.py", line 98, in receive
    return self.receive_nowait()
  File "/home/omar/.local/lib/python3.10/site-packages/anyio/streams/memory.py", line 93, in receive_nowait
    raise WouldBlock
anyio.WouldBlock

During handling of the above exception, another exception occurred:

Traceback (most recent call last):
  File "/home/omar/.local/lib/python3.10/site-packages/starlette/middleware/base.py", line 159, in call_next
    message = await recv_stream.receive()
  File "/home/omar/.local/lib/python3.10/site-packages/anyio/streams/memory.py", line 118, in receive
    raise EndOfStream
anyio.EndOfStream

During handling of the above exception, another exception occurred:

Traceback (most recent call last):
  File "/home/omar/.local/lib/python3.10/site-packages/chromadb/server/fastapi/__init__.py", line 82, in catch_exceptions_middleware
    return await call_next(request)
  File "/home/omar/.local/lib/python3.10/site-packages/starlette/middleware/base.py", line 165, in call_next
    raise app_exc
  File "/home/omar/.local/lib/python3.10/site-packages/starlette/middleware/base.py", line 151, in coro
    await self.app(scope, receive_or_disconnect, send_no_error)
  File "/home/omar/.local/lib/python3.10/site-packages/starlette/middleware/base.py", line 191, in __call__
    response = await self.dispatch_func(request, call_next)
  File "/home/omar/.local/lib/python3.10/site-packages/chromadb/server/fastapi/__init__.py", line 96, in check_http_version_middleware
    return await call_next(request)
  File "/home/omar/.local/lib/python3.10/site-packages/starlette/middleware/base.py", line 165, in call_next
    raise app_exc
  File "/home/omar/.local/lib/python3.10/site-packages/starlette/middleware/base.py", line 151, in coro
    await self.app(scope, receive_or_disconnect, send_no_error)
  File "/home/omar/.local/lib/python3.10/site-packages/starlette/middleware/exceptions.py", line 65, in __call__
    await wrap_app_handling_exceptions(self.app, conn)(scope, receive, send)
  File "/home/omar/.local/lib/python3.10/site-packages/starlette/_exception_handler.py", line 64, in wrapped_app
    raise exc
  File "/home/omar/.local/lib/python3.10/site-packages/starlette/_exception_handler.py", line 53, in wrapped_app
    await app(scope, receive, sender)
  File "/home/omar/.local/lib/python3.10/site-packages/starlette/routing.py", line 756, in __call__
    await self.middleware_stack(scope, receive, send)
  File "/home/omar/.local/lib/python3.10/site-packages/starlette/routing.py", line 776, in app
    await route.handle(scope, receive, send)
  File "/home/omar/.local/lib/python3.10/site-packages/starlette/routing.py", line 297, in handle
    await self.app(scope, receive, send)
  File "/home/omar/.local/lib/python3.10/site-packages/starlette/routing.py", line 77, in app
    await wrap_app_handling_exceptions(app, request)(scope, receive, send)
  File "/home/omar/.local/lib/python3.10/site-packages/starlette/_exception_handler.py", line 64, in wrapped_app
    raise exc
  File "/home/omar/.local/lib/python3.10/site-packages/starlette/_exception_handler.py", line 53, in wrapped_app
    await app(scope, receive, sender)
  File "/home/omar/.local/lib/python3.10/site-packages/starlette/routing.py", line 72, in app
    response = await func(request)
  File "/home/omar/.local/lib/python3.10/site-packages/fastapi/routing.py", line 278, in app
    raw_response = await run_endpoint_function(
  File "/home/omar/.local/lib/python3.10/site-packages/fastapi/routing.py", line 193, in run_endpoint_function
    return await run_in_threadpool(dependant.call, **values)
  File "/home/omar/.local/lib/python3.10/site-packages/starlette/concurrency.py", line 42, in run_in_threadpool
    return await anyio.to_thread.run_sync(func, *args)
  File "/home/omar/.local/lib/python3.10/site-packages/anyio/to_thread.py", line 33, in run_sync
    return await get_asynclib().run_sync_in_worker_thread(
  File "/home/omar/.local/lib/python3.10/site-packages/anyio/_backends/_asyncio.py", line 877, in run_sync_in_worker_thread
    return await future
  File "/home/omar/.local/lib/python3.10/site-packages/anyio/_backends/_asyncio.py", line 807, in run
    result = context.run(func, *args)
  File "/home/omar/.local/lib/python3.10/site-packages/chromadb/telemetry/opentelemetry/__init__.py", line 127, in wrapper
    return f(*args, **kwargs)
  File "/home/omar/.local/lib/python3.10/site-packages/chromadb/auth/fastapi.py", line 241, in wrapped
    return f(*args, **kwargs)
  File "/home/omar/.local/lib/python3.10/site-packages/chromadb/server/fastapi/__init__.py", line 415, in create_collection
    return self._api.create_collection(
  File "/home/omar/.local/lib/python3.10/site-packages/chromadb/telemetry/opentelemetry/__init__.py", line 127, in wrapper
    return f(*args, **kwargs)
  File "/home/omar/.local/lib/python3.10/site-packages/chromadb/api/segment.py", line 167, in create_collection
    coll, created = self._sysdb.create_collection(
  File "/home/omar/.local/lib/python3.10/site-packages/chromadb/telemetry/opentelemetry/__init__.py", line 127, in wrapper
    return f(*args, **kwargs)
  File "/home/omar/.local/lib/python3.10/site-packages/chromadb/db/mixins/sysdb.py", line 225, in create_collection
    raise UniqueConstraintError(f"Collection {name} already exists")
chromadb.db.base.UniqueConstraintError: Collection test-from-js already exists
[32mINFO[0m:     [07-04-2024 14:47:02] 127.0.0.1:50318 - "POST /api/v1/collections?tenant=default_tenant&database=default_database HTTP/1.1" 500
[31mERROR[0m:    [07-04-2024 14:47:18] Collection test-from-js already exists
Traceback (most recent call last):
  File "/home/omar/.local/lib/python3.10/site-packages/anyio/streams/memory.py", line 98, in receive
    return self.receive_nowait()
  File "/home/omar/.local/lib/python3.10/site-packages/anyio/streams/memory.py", line 93, in receive_nowait
    raise WouldBlock
anyio.WouldBlock

During handling of the above exception, another exception occurred:

Traceback (most recent call last):
  File "/home/omar/.local/lib/python3.10/site-packages/starlette/middleware/base.py", line 159, in call_next
    message = await recv_stream.receive()
  File "/home/omar/.local/lib/python3.10/site-packages/anyio/streams/memory.py", line 118, in receive
    raise EndOfStream
anyio.EndOfStream

During handling of the above exception, another exception occurred:

Traceback (most recent call last):
  File "/home/omar/.local/lib/python3.10/site-packages/chromadb/server/fastapi/__init__.py", line 82, in catch_exceptions_middleware
    return await call_next(request)
  File "/home/omar/.local/lib/python3.10/site-packages/starlette/middleware/base.py", line 165, in call_next
    raise app_exc
  File "/home/omar/.local/lib/python3.10/site-packages/starlette/middleware/base.py", line 151, in coro
    await self.app(scope, receive_or_disconnect, send_no_error)
  File "/home/omar/.local/lib/python3.10/site-packages/starlette/middleware/base.py", line 191, in __call__
    response = await self.dispatch_func(request, call_next)
  File "/home/omar/.local/lib/python3.10/site-packages/chromadb/server/fastapi/__init__.py", line 96, in check_http_version_middleware
    return await call_next(request)
  File "/home/omar/.local/lib/python3.10/site-packages/starlette/middleware/base.py", line 165, in call_next
    raise app_exc
  File "/home/omar/.local/lib/python3.10/site-packages/starlette/middleware/base.py", line 151, in coro
    await self.app(scope, receive_or_disconnect, send_no_error)
  File "/home/omar/.local/lib/python3.10/site-packages/starlette/middleware/exceptions.py", line 65, in __call__
    await wrap_app_handling_exceptions(self.app, conn)(scope, receive, send)
  File "/home/omar/.local/lib/python3.10/site-packages/starlette/_exception_handler.py", line 64, in wrapped_app
    raise exc
  File "/home/omar/.local/lib/python3.10/site-packages/starlette/_exception_handler.py", line 53, in wrapped_app
    await app(scope, receive, sender)
  File "/home/omar/.local/lib/python3.10/site-packages/starlette/routing.py", line 756, in __call__
    await self.middleware_stack(scope, receive, send)
  File "/home/omar/.local/lib/python3.10/site-packages/starlette/routing.py", line 776, in app
    await route.handle(scope, receive, send)
  File "/home/omar/.local/lib/python3.10/site-packages/starlette/routing.py", line 297, in handle
    await self.app(scope, receive, send)
  File "/home/omar/.local/lib/python3.10/site-packages/starlette/routing.py", line 77, in app
    await wrap_app_handling_exceptions(app, request)(scope, receive, send)
  File "/home/omar/.local/lib/python3.10/site-packages/starlette/_exception_handler.py", line 64, in wrapped_app
    raise exc
  File "/home/omar/.local/lib/python3.10/site-packages/starlette/_exception_handler.py", line 53, in wrapped_app
    await app(scope, receive, sender)
  File "/home/omar/.local/lib/python3.10/site-packages/starlette/routing.py", line 72, in app
    response = await func(request)
  File "/home/omar/.local/lib/python3.10/site-packages/fastapi/routing.py", line 278, in app
    raw_response = await run_endpoint_function(
  File "/home/omar/.local/lib/python3.10/site-packages/fastapi/routing.py", line 193, in run_endpoint_function
    return await run_in_threadpool(dependant.call, **values)
  File "/home/omar/.local/lib/python3.10/site-packages/starlette/concurrency.py", line 42, in run_in_threadpool
    return await anyio.to_thread.run_sync(func, *args)
  File "/home/omar/.local/lib/python3.10/site-packages/anyio/to_thread.py", line 33, in run_sync
    return await get_asynclib().run_sync_in_worker_thread(
  File "/home/omar/.local/lib/python3.10/site-packages/anyio/_backends/_asyncio.py", line 877, in run_sync_in_worker_thread
    return await future
  File "/home/omar/.local/lib/python3.10/site-packages/anyio/_backends/_asyncio.py", line 807, in run
    result = context.run(func, *args)
  File "/home/omar/.local/lib/python3.10/site-packages/chromadb/telemetry/opentelemetry/__init__.py", line 127, in wrapper
    return f(*args, **kwargs)
  File "/home/omar/.local/lib/python3.10/site-packages/chromadb/auth/fastapi.py", line 241, in wrapped
    return f(*args, **kwargs)
  File "/home/omar/.local/lib/python3.10/site-packages/chromadb/server/fastapi/__init__.py", line 415, in create_collection
    return self._api.create_collection(
  File "/home/omar/.local/lib/python3.10/site-packages/chromadb/telemetry/opentelemetry/__init__.py", line 127, in wrapper
    return f(*args, **kwargs)
  File "/home/omar/.local/lib/python3.10/site-packages/chromadb/api/segment.py", line 167, in create_collection
    coll, created = self._sysdb.create_collection(
  File "/home/omar/.local/lib/python3.10/site-packages/chromadb/telemetry/opentelemetry/__init__.py", line 127, in wrapper
    return f(*args, **kwargs)
  File "/home/omar/.local/lib/python3.10/site-packages/chromadb/db/mixins/sysdb.py", line 225, in create_collection
    raise UniqueConstraintError(f"Collection {name} already exists")
chromadb.db.base.UniqueConstraintError: Collection test-from-js already exists
[32mINFO[0m:     [07-04-2024 14:47:18] 127.0.0.1:49592 - "POST /api/v1/collections?tenant=default_tenant&database=default_database HTTP/1.1" 500
[31mERROR[0m:    [07-04-2024 14:51:57] Collection test-from-js already exists
Traceback (most recent call last):
  File "/home/omar/.local/lib/python3.10/site-packages/anyio/streams/memory.py", line 98, in receive
    return self.receive_nowait()
  File "/home/omar/.local/lib/python3.10/site-packages/anyio/streams/memory.py", line 93, in receive_nowait
    raise WouldBlock
anyio.WouldBlock

During handling of the above exception, another exception occurred:

Traceback (most recent call last):
  File "/home/omar/.local/lib/python3.10/site-packages/starlette/middleware/base.py", line 159, in call_next
    message = await recv_stream.receive()
  File "/home/omar/.local/lib/python3.10/site-packages/anyio/streams/memory.py", line 118, in receive
    raise EndOfStream
anyio.EndOfStream

During handling of the above exception, another exception occurred:

Traceback (most recent call last):
  File "/home/omar/.local/lib/python3.10/site-packages/chromadb/server/fastapi/__init__.py", line 82, in catch_exceptions_middleware
    return await call_next(request)
  File "/home/omar/.local/lib/python3.10/site-packages/starlette/middleware/base.py", line 165, in call_next
    raise app_exc
  File "/home/omar/.local/lib/python3.10/site-packages/starlette/middleware/base.py", line 151, in coro
    await self.app(scope, receive_or_disconnect, send_no_error)
  File "/home/omar/.local/lib/python3.10/site-packages/starlette/middleware/base.py", line 191, in __call__
    response = await self.dispatch_func(request, call_next)
  File "/home/omar/.local/lib/python3.10/site-packages/chromadb/server/fastapi/__init__.py", line 96, in check_http_version_middleware
    return await call_next(request)
  File "/home/omar/.local/lib/python3.10/site-packages/starlette/middleware/base.py", line 165, in call_next
    raise app_exc
  File "/home/omar/.local/lib/python3.10/site-packages/starlette/middleware/base.py", line 151, in coro
    await self.app(scope, receive_or_disconnect, send_no_error)
  File "/home/omar/.local/lib/python3.10/site-packages/starlette/middleware/exceptions.py", line 65, in __call__
    await wrap_app_handling_exceptions(self.app, conn)(scope, receive, send)
  File "/home/omar/.local/lib/python3.10/site-packages/starlette/_exception_handler.py", line 64, in wrapped_app
    raise exc
  File "/home/omar/.local/lib/python3.10/site-packages/starlette/_exception_handler.py", line 53, in wrapped_app
    await app(scope, receive, sender)
  File "/home/omar/.local/lib/python3.10/site-packages/starlette/routing.py", line 756, in __call__
    await self.middleware_stack(scope, receive, send)
  File "/home/omar/.local/lib/python3.10/site-packages/starlette/routing.py", line 776, in app
    await route.handle(scope, receive, send)
  File "/home/omar/.local/lib/python3.10/site-packages/starlette/routing.py", line 297, in handle
    await self.app(scope, receive, send)
  File "/home/omar/.local/lib/python3.10/site-packages/starlette/routing.py", line 77, in app
    await wrap_app_handling_exceptions(app, request)(scope, receive, send)
  File "/home/omar/.local/lib/python3.10/site-packages/starlette/_exception_handler.py", line 64, in wrapped_app
    raise exc
  File "/home/omar/.local/lib/python3.10/site-packages/starlette/_exception_handler.py", line 53, in wrapped_app
    await app(scope, receive, sender)
  File "/home/omar/.local/lib/python3.10/site-packages/starlette/routing.py", line 72, in app
    response = await func(request)
  File "/home/omar/.local/lib/python3.10/site-packages/fastapi/routing.py", line 278, in app
    raw_response = await run_endpoint_function(
  File "/home/omar/.local/lib/python3.10/site-packages/fastapi/routing.py", line 193, in run_endpoint_function
    return await run_in_threadpool(dependant.call, **values)
  File "/home/omar/.local/lib/python3.10/site-packages/starlette/concurrency.py", line 42, in run_in_threadpool
    return await anyio.to_thread.run_sync(func, *args)
  File "/home/omar/.local/lib/python3.10/site-packages/anyio/to_thread.py", line 33, in run_sync
    return await get_asynclib().run_sync_in_worker_thread(
  File "/home/omar/.local/lib/python3.10/site-packages/anyio/_backends/_asyncio.py", line 877, in run_sync_in_worker_thread
    return await future
  File "/home/omar/.local/lib/python3.10/site-packages/anyio/_backends/_asyncio.py", line 807, in run
    result = context.run(func, *args)
  File "/home/omar/.local/lib/python3.10/site-packages/chromadb/telemetry/opentelemetry/__init__.py", line 127, in wrapper
    return f(*args, **kwargs)
  File "/home/omar/.local/lib/python3.10/site-packages/chromadb/auth/fastapi.py", line 241, in wrapped
    return f(*args, **kwargs)
  File "/home/omar/.local/lib/python3.10/site-packages/chromadb/server/fastapi/__init__.py", line 415, in create_collection
    return self._api.create_collection(
  File "/home/omar/.local/lib/python3.10/site-packages/chromadb/telemetry/opentelemetry/__init__.py", line 127, in wrapper
    return f(*args, **kwargs)
  File "/home/omar/.local/lib/python3.10/site-packages/chromadb/api/segment.py", line 167, in create_collection
    coll, created = self._sysdb.create_collection(
  File "/home/omar/.local/lib/python3.10/site-packages/chromadb/telemetry/opentelemetry/__init__.py", line 127, in wrapper
    return f(*args, **kwargs)
  File "/home/omar/.local/lib/python3.10/site-packages/chromadb/db/mixins/sysdb.py", line 225, in create_collection
    raise UniqueConstraintError(f"Collection {name} already exists")
chromadb.db.base.UniqueConstraintError: Collection test-from-js already exists
[32mINFO[0m:     [07-04-2024 14:51:57] 127.0.0.1:53942 - "POST /api/v1/collections?tenant=default_tenant&database=default_database HTTP/1.1" 500
[32mINFO[0m:     [07-04-2024 14:57:32] 127.0.0.1:42370 - "POST /api/v1/collections?tenant=default_tenant&database=default_database HTTP/1.1" 200
[31mERROR[0m:    [07-04-2024 14:58:03] Collection test-collection already exists
Traceback (most recent call last):
  File "/home/omar/.local/lib/python3.10/site-packages/anyio/streams/memory.py", line 98, in receive
    return self.receive_nowait()
  File "/home/omar/.local/lib/python3.10/site-packages/anyio/streams/memory.py", line 93, in receive_nowait
    raise WouldBlock
anyio.WouldBlock

During handling of the above exception, another exception occurred:

Traceback (most recent call last):
  File "/home/omar/.local/lib/python3.10/site-packages/starlette/middleware/base.py", line 159, in call_next
    message = await recv_stream.receive()
  File "/home/omar/.local/lib/python3.10/site-packages/anyio/streams/memory.py", line 118, in receive
    raise EndOfStream
anyio.EndOfStream

During handling of the above exception, another exception occurred:

Traceback (most recent call last):
  File "/home/omar/.local/lib/python3.10/site-packages/chromadb/server/fastapi/__init__.py", line 82, in catch_exceptions_middleware
    return await call_next(request)
  File "/home/omar/.local/lib/python3.10/site-packages/starlette/middleware/base.py", line 165, in call_next
    raise app_exc
  File "/home/omar/.local/lib/python3.10/site-packages/starlette/middleware/base.py", line 151, in coro
    await self.app(scope, receive_or_disconnect, send_no_error)
  File "/home/omar/.local/lib/python3.10/site-packages/starlette/middleware/base.py", line 191, in __call__
    response = await self.dispatch_func(request, call_next)
  File "/home/omar/.local/lib/python3.10/site-packages/chromadb/server/fastapi/__init__.py", line 96, in check_http_version_middleware
    return await call_next(request)
  File "/home/omar/.local/lib/python3.10/site-packages/starlette/middleware/base.py", line 165, in call_next
    raise app_exc
  File "/home/omar/.local/lib/python3.10/site-packages/starlette/middleware/base.py", line 151, in coro
    await self.app(scope, receive_or_disconnect, send_no_error)
  File "/home/omar/.local/lib/python3.10/site-packages/starlette/middleware/exceptions.py", line 65, in __call__
    await wrap_app_handling_exceptions(self.app, conn)(scope, receive, send)
  File "/home/omar/.local/lib/python3.10/site-packages/starlette/_exception_handler.py", line 64, in wrapped_app
    raise exc
  File "/home/omar/.local/lib/python3.10/site-packages/starlette/_exception_handler.py", line 53, in wrapped_app
    await app(scope, receive, sender)
  File "/home/omar/.local/lib/python3.10/site-packages/starlette/routing.py", line 756, in __call__
    await self.middleware_stack(scope, receive, send)
  File "/home/omar/.local/lib/python3.10/site-packages/starlette/routing.py", line 776, in app
    await route.handle(scope, receive, send)
  File "/home/omar/.local/lib/python3.10/site-packages/starlette/routing.py", line 297, in handle
    await self.app(scope, receive, send)
  File "/home/omar/.local/lib/python3.10/site-packages/starlette/routing.py", line 77, in app
    await wrap_app_handling_exceptions(app, request)(scope, receive, send)
  File "/home/omar/.local/lib/python3.10/site-packages/starlette/_exception_handler.py", line 64, in wrapped_app
    raise exc
  File "/home/omar/.local/lib/python3.10/site-packages/starlette/_exception_handler.py", line 53, in wrapped_app
    await app(scope, receive, sender)
  File "/home/omar/.local/lib/python3.10/site-packages/starlette/routing.py", line 72, in app
    response = await func(request)
  File "/home/omar/.local/lib/python3.10/site-packages/fastapi/routing.py", line 278, in app
    raw_response = await run_endpoint_function(
  File "/home/omar/.local/lib/python3.10/site-packages/fastapi/routing.py", line 193, in run_endpoint_function
    return await run_in_threadpool(dependant.call, **values)
  File "/home/omar/.local/lib/python3.10/site-packages/starlette/concurrency.py", line 42, in run_in_threadpool
    return await anyio.to_thread.run_sync(func, *args)
  File "/home/omar/.local/lib/python3.10/site-packages/anyio/to_thread.py", line 33, in run_sync
    return await get_asynclib().run_sync_in_worker_thread(
  File "/home/omar/.local/lib/python3.10/site-packages/anyio/_backends/_asyncio.py", line 877, in run_sync_in_worker_thread
    return await future
  File "/home/omar/.local/lib/python3.10/site-packages/anyio/_backends/_asyncio.py", line 807, in run
    result = context.run(func, *args)
  File "/home/omar/.local/lib/python3.10/site-packages/chromadb/telemetry/opentelemetry/__init__.py", line 127, in wrapper
    return f(*args, **kwargs)
  File "/home/omar/.local/lib/python3.10/site-packages/chromadb/auth/fastapi.py", line 241, in wrapped
    return f(*args, **kwargs)
  File "/home/omar/.local/lib/python3.10/site-packages/chromadb/server/fastapi/__init__.py", line 415, in create_collection
    return self._api.create_collection(
  File "/home/omar/.local/lib/python3.10/site-packages/chromadb/telemetry/opentelemetry/__init__.py", line 127, in wrapper
    return f(*args, **kwargs)
  File "/home/omar/.local/lib/python3.10/site-packages/chromadb/api/segment.py", line 167, in create_collection
    coll, created = self._sysdb.create_collection(
  File "/home/omar/.local/lib/python3.10/site-packages/chromadb/telemetry/opentelemetry/__init__.py", line 127, in wrapper
    return f(*args, **kwargs)
  File "/home/omar/.local/lib/python3.10/site-packages/chromadb/db/mixins/sysdb.py", line 225, in create_collection
    raise UniqueConstraintError(f"Collection {name} already exists")
chromadb.db.base.UniqueConstraintError: Collection test-collection already exists
[32mINFO[0m:     [07-04-2024 14:58:03] 127.0.0.1:57666 - "POST /api/v1/collections?tenant=default_tenant&database=default_database HTTP/1.1" 500
[31mERROR[0m:    [07-04-2024 14:58:55] Collection test-collection already exists
Traceback (most recent call last):
  File "/home/omar/.local/lib/python3.10/site-packages/anyio/streams/memory.py", line 98, in receive
    return self.receive_nowait()
  File "/home/omar/.local/lib/python3.10/site-packages/anyio/streams/memory.py", line 93, in receive_nowait
    raise WouldBlock
anyio.WouldBlock

During handling of the above exception, another exception occurred:

Traceback (most recent call last):
  File "/home/omar/.local/lib/python3.10/site-packages/starlette/middleware/base.py", line 159, in call_next
    message = await recv_stream.receive()
  File "/home/omar/.local/lib/python3.10/site-packages/anyio/streams/memory.py", line 118, in receive
    raise EndOfStream
anyio.EndOfStream

During handling of the above exception, another exception occurred:

Traceback (most recent call last):
  File "/home/omar/.local/lib/python3.10/site-packages/chromadb/server/fastapi/__init__.py", line 82, in catch_exceptions_middleware
    return await call_next(request)
  File "/home/omar/.local/lib/python3.10/site-packages/starlette/middleware/base.py", line 165, in call_next
    raise app_exc
  File "/home/omar/.local/lib/python3.10/site-packages/starlette/middleware/base.py", line 151, in coro
    await self.app(scope, receive_or_disconnect, send_no_error)
  File "/home/omar/.local/lib/python3.10/site-packages/starlette/middleware/base.py", line 191, in __call__
    response = await self.dispatch_func(request, call_next)
  File "/home/omar/.local/lib/python3.10/site-packages/chromadb/server/fastapi/__init__.py", line 96, in check_http_version_middleware
    return await call_next(request)
  File "/home/omar/.local/lib/python3.10/site-packages/starlette/middleware/base.py", line 165, in call_next
    raise app_exc
  File "/home/omar/.local/lib/python3.10/site-packages/starlette/middleware/base.py", line 151, in coro
    await self.app(scope, receive_or_disconnect, send_no_error)
  File "/home/omar/.local/lib/python3.10/site-packages/starlette/middleware/exceptions.py", line 65, in __call__
    await wrap_app_handling_exceptions(self.app, conn)(scope, receive, send)
  File "/home/omar/.local/lib/python3.10/site-packages/starlette/_exception_handler.py", line 64, in wrapped_app
    raise exc
  File "/home/omar/.local/lib/python3.10/site-packages/starlette/_exception_handler.py", line 53, in wrapped_app
    await app(scope, receive, sender)
  File "/home/omar/.local/lib/python3.10/site-packages/starlette/routing.py", line 756, in __call__
    await self.middleware_stack(scope, receive, send)
  File "/home/omar/.local/lib/python3.10/site-packages/starlette/routing.py", line 776, in app
    await route.handle(scope, receive, send)
  File "/home/omar/.local/lib/python3.10/site-packages/starlette/routing.py", line 297, in handle
    await self.app(scope, receive, send)
  File "/home/omar/.local/lib/python3.10/site-packages/starlette/routing.py", line 77, in app
    await wrap_app_handling_exceptions(app, request)(scope, receive, send)
  File "/home/omar/.local/lib/python3.10/site-packages/starlette/_exception_handler.py", line 64, in wrapped_app
    raise exc
  File "/home/omar/.local/lib/python3.10/site-packages/starlette/_exception_handler.py", line 53, in wrapped_app
    await app(scope, receive, sender)
  File "/home/omar/.local/lib/python3.10/site-packages/starlette/routing.py", line 72, in app
    response = await func(request)
  File "/home/omar/.local/lib/python3.10/site-packages/fastapi/routing.py", line 278, in app
    raw_response = await run_endpoint_function(
  File "/home/omar/.local/lib/python3.10/site-packages/fastapi/routing.py", line 193, in run_endpoint_function
    return await run_in_threadpool(dependant.call, **values)
  File "/home/omar/.local/lib/python3.10/site-packages/starlette/concurrency.py", line 42, in run_in_threadpool
    return await anyio.to_thread.run_sync(func, *args)
  File "/home/omar/.local/lib/python3.10/site-packages/anyio/to_thread.py", line 33, in run_sync
    return await get_asynclib().run_sync_in_worker_thread(
  File "/home/omar/.local/lib/python3.10/site-packages/anyio/_backends/_asyncio.py", line 877, in run_sync_in_worker_thread
    return await future
  File "/home/omar/.local/lib/python3.10/site-packages/anyio/_backends/_asyncio.py", line 807, in run
    result = context.run(func, *args)
  File "/home/omar/.local/lib/python3.10/site-packages/chromadb/telemetry/opentelemetry/__init__.py", line 127, in wrapper
    return f(*args, **kwargs)
  File "/home/omar/.local/lib/python3.10/site-packages/chromadb/auth/fastapi.py", line 241, in wrapped
    return f(*args, **kwargs)
  File "/home/omar/.local/lib/python3.10/site-packages/chromadb/server/fastapi/__init__.py", line 415, in create_collection
    return self._api.create_collection(
  File "/home/omar/.local/lib/python3.10/site-packages/chromadb/telemetry/opentelemetry/__init__.py", line 127, in wrapper
    return f(*args, **kwargs)
  File "/home/omar/.local/lib/python3.10/site-packages/chromadb/api/segment.py", line 167, in create_collection
    coll, created = self._sysdb.create_collection(
  File "/home/omar/.local/lib/python3.10/site-packages/chromadb/telemetry/opentelemetry/__init__.py", line 127, in wrapper
    return f(*args, **kwargs)
  File "/home/omar/.local/lib/python3.10/site-packages/chromadb/db/mixins/sysdb.py", line 225, in create_collection
    raise UniqueConstraintError(f"Collection {name} already exists")
chromadb.db.base.UniqueConstraintError: Collection test-collection already exists
[32mINFO[0m:     [07-04-2024 14:58:55] 127.0.0.1:57086 - "POST /api/v1/collections?tenant=default_tenant&database=default_database HTTP/1.1" 500
[31mERROR[0m:    [07-04-2024 14:59:10] Collection test-collection already exists
Traceback (most recent call last):
  File "/home/omar/.local/lib/python3.10/site-packages/anyio/streams/memory.py", line 98, in receive
    return self.receive_nowait()
  File "/home/omar/.local/lib/python3.10/site-packages/anyio/streams/memory.py", line 93, in receive_nowait
    raise WouldBlock
anyio.WouldBlock

During handling of the above exception, another exception occurred:

Traceback (most recent call last):
  File "/home/omar/.local/lib/python3.10/site-packages/starlette/middleware/base.py", line 159, in call_next
    message = await recv_stream.receive()
  File "/home/omar/.local/lib/python3.10/site-packages/anyio/streams/memory.py", line 118, in receive
    raise EndOfStream
anyio.EndOfStream

During handling of the above exception, another exception occurred:

Traceback (most recent call last):
  File "/home/omar/.local/lib/python3.10/site-packages/chromadb/server/fastapi/__init__.py", line 82, in catch_exceptions_middleware
    return await call_next(request)
  File "/home/omar/.local/lib/python3.10/site-packages/starlette/middleware/base.py", line 165, in call_next
    raise app_exc
  File "/home/omar/.local/lib/python3.10/site-packages/starlette/middleware/base.py", line 151, in coro
    await self.app(scope, receive_or_disconnect, send_no_error)
  File "/home/omar/.local/lib/python3.10/site-packages/starlette/middleware/base.py", line 191, in __call__
    response = await self.dispatch_func(request, call_next)
  File "/home/omar/.local/lib/python3.10/site-packages/chromadb/server/fastapi/__init__.py", line 96, in check_http_version_middleware
    return await call_next(request)
  File "/home/omar/.local/lib/python3.10/site-packages/starlette/middleware/base.py", line 165, in call_next
    raise app_exc
  File "/home/omar/.local/lib/python3.10/site-packages/starlette/middleware/base.py", line 151, in coro
    await self.app(scope, receive_or_disconnect, send_no_error)
  File "/home/omar/.local/lib/python3.10/site-packages/starlette/middleware/exceptions.py", line 65, in __call__
    await wrap_app_handling_exceptions(self.app, conn)(scope, receive, send)
  File "/home/omar/.local/lib/python3.10/site-packages/starlette/_exception_handler.py", line 64, in wrapped_app
    raise exc
  File "/home/omar/.local/lib/python3.10/site-packages/starlette/_exception_handler.py", line 53, in wrapped_app
    await app(scope, receive, sender)
  File "/home/omar/.local/lib/python3.10/site-packages/starlette/routing.py", line 756, in __call__
    await self.middleware_stack(scope, receive, send)
  File "/home/omar/.local/lib/python3.10/site-packages/starlette/routing.py", line 776, in app
    await route.handle(scope, receive, send)
  File "/home/omar/.local/lib/python3.10/site-packages/starlette/routing.py", line 297, in handle
    await self.app(scope, receive, send)
  File "/home/omar/.local/lib/python3.10/site-packages/starlette/routing.py", line 77, in app
    await wrap_app_handling_exceptions(app, request)(scope, receive, send)
  File "/home/omar/.local/lib/python3.10/site-packages/starlette/_exception_handler.py", line 64, in wrapped_app
    raise exc
  File "/home/omar/.local/lib/python3.10/site-packages/starlette/_exception_handler.py", line 53, in wrapped_app
    await app(scope, receive, sender)
  File "/home/omar/.local/lib/python3.10/site-packages/starlette/routing.py", line 72, in app
    response = await func(request)
  File "/home/omar/.local/lib/python3.10/site-packages/fastapi/routing.py", line 278, in app
    raw_response = await run_endpoint_function(
  File "/home/omar/.local/lib/python3.10/site-packages/fastapi/routing.py", line 193, in run_endpoint_function
    return await run_in_threadpool(dependant.call, **values)
  File "/home/omar/.local/lib/python3.10/site-packages/starlette/concurrency.py", line 42, in run_in_threadpool
    return await anyio.to_thread.run_sync(func, *args)
  File "/home/omar/.local/lib/python3.10/site-packages/anyio/to_thread.py", line 33, in run_sync
    return await get_asynclib().run_sync_in_worker_thread(
  File "/home/omar/.local/lib/python3.10/site-packages/anyio/_backends/_asyncio.py", line 877, in run_sync_in_worker_thread
    return await future
  File "/home/omar/.local/lib/python3.10/site-packages/anyio/_backends/_asyncio.py", line 807, in run
    result = context.run(func, *args)
  File "/home/omar/.local/lib/python3.10/site-packages/chromadb/telemetry/opentelemetry/__init__.py", line 127, in wrapper
    return f(*args, **kwargs)
  File "/home/omar/.local/lib/python3.10/site-packages/chromadb/auth/fastapi.py", line 241, in wrapped
    return f(*args, **kwargs)
  File "/home/omar/.local/lib/python3.10/site-packages/chromadb/server/fastapi/__init__.py", line 415, in create_collection
    return self._api.create_collection(
  File "/home/omar/.local/lib/python3.10/site-packages/chromadb/telemetry/opentelemetry/__init__.py", line 127, in wrapper
    return f(*args, **kwargs)
  File "/home/omar/.local/lib/python3.10/site-packages/chromadb/api/segment.py", line 167, in create_collection
    coll, created = self._sysdb.create_collection(
  File "/home/omar/.local/lib/python3.10/site-packages/chromadb/telemetry/opentelemetry/__init__.py", line 127, in wrapper
    return f(*args, **kwargs)
  File "/home/omar/.local/lib/python3.10/site-packages/chromadb/db/mixins/sysdb.py", line 225, in create_collection
    raise UniqueConstraintError(f"Collection {name} already exists")
chromadb.db.base.UniqueConstraintError: Collection test-collection already exists
[32mINFO[0m:     [07-04-2024 14:59:10] 127.0.0.1:38084 - "POST /api/v1/collections?tenant=default_tenant&database=default_database HTTP/1.1" 500
[31mERROR[0m:    [07-04-2024 14:59:10] Collection test-collection already exists
Traceback (most recent call last):
  File "/home/omar/.local/lib/python3.10/site-packages/anyio/streams/memory.py", line 98, in receive
    return self.receive_nowait()
  File "/home/omar/.local/lib/python3.10/site-packages/anyio/streams/memory.py", line 93, in receive_nowait
    raise WouldBlock
anyio.WouldBlock

During handling of the above exception, another exception occurred:

Traceback (most recent call last):
  File "/home/omar/.local/lib/python3.10/site-packages/starlette/middleware/base.py", line 159, in call_next
    message = await recv_stream.receive()
  File "/home/omar/.local/lib/python3.10/site-packages/anyio/streams/memory.py", line 118, in receive
    raise EndOfStream
anyio.EndOfStream

During handling of the above exception, another exception occurred:

Traceback (most recent call last):
  File "/home/omar/.local/lib/python3.10/site-packages/chromadb/server/fastapi/__init__.py", line 82, in catch_exceptions_middleware
    return await call_next(request)
  File "/home/omar/.local/lib/python3.10/site-packages/starlette/middleware/base.py", line 165, in call_next
    raise app_exc
  File "/home/omar/.local/lib/python3.10/site-packages/starlette/middleware/base.py", line 151, in coro
    await self.app(scope, receive_or_disconnect, send_no_error)
  File "/home/omar/.local/lib/python3.10/site-packages/starlette/middleware/base.py", line 191, in __call__
    response = await self.dispatch_func(request, call_next)
  File "/home/omar/.local/lib/python3.10/site-packages/chromadb/server/fastapi/__init__.py", line 96, in check_http_version_middleware
    return await call_next(request)
  File "/home/omar/.local/lib/python3.10/site-packages/starlette/middleware/base.py", line 165, in call_next
    raise app_exc
  File "/home/omar/.local/lib/python3.10/site-packages/starlette/middleware/base.py", line 151, in coro
    await self.app(scope, receive_or_disconnect, send_no_error)
  File "/home/omar/.local/lib/python3.10/site-packages/starlette/middleware/exceptions.py", line 65, in __call__
    await wrap_app_handling_exceptions(self.app, conn)(scope, receive, send)
  File "/home/omar/.local/lib/python3.10/site-packages/starlette/_exception_handler.py", line 64, in wrapped_app
    raise exc
  File "/home/omar/.local/lib/python3.10/site-packages/starlette/_exception_handler.py", line 53, in wrapped_app
    await app(scope, receive, sender)
  File "/home/omar/.local/lib/python3.10/site-packages/starlette/routing.py", line 756, in __call__
    await self.middleware_stack(scope, receive, send)
  File "/home/omar/.local/lib/python3.10/site-packages/starlette/routing.py", line 776, in app
    await route.handle(scope, receive, send)
  File "/home/omar/.local/lib/python3.10/site-packages/starlette/routing.py", line 297, in handle
    await self.app(scope, receive, send)
  File "/home/omar/.local/lib/python3.10/site-packages/starlette/routing.py", line 77, in app
    await wrap_app_handling_exceptions(app, request)(scope, receive, send)
  File "/home/omar/.local/lib/python3.10/site-packages/starlette/_exception_handler.py", line 64, in wrapped_app
    raise exc
  File "/home/omar/.local/lib/python3.10/site-packages/starlette/_exception_handler.py", line 53, in wrapped_app
    await app(scope, receive, sender)
  File "/home/omar/.local/lib/python3.10/site-packages/starlette/routing.py", line 72, in app
    response = await func(request)
  File "/home/omar/.local/lib/python3.10/site-packages/fastapi/routing.py", line 278, in app
    raw_response = await run_endpoint_function(
  File "/home/omar/.local/lib/python3.10/site-packages/fastapi/routing.py", line 193, in run_endpoint_function
    return await run_in_threadpool(dependant.call, **values)
  File "/home/omar/.local/lib/python3.10/site-packages/starlette/concurrency.py", line 42, in run_in_threadpool
    return await anyio.to_thread.run_sync(func, *args)
  File "/home/omar/.local/lib/python3.10/site-packages/anyio/to_thread.py", line 33, in run_sync
    return await get_asynclib().run_sync_in_worker_thread(
  File "/home/omar/.local/lib/python3.10/site-packages/anyio/_backends/_asyncio.py", line 877, in run_sync_in_worker_thread
    return await future
  File "/home/omar/.local/lib/python3.10/site-packages/anyio/_backends/_asyncio.py", line 807, in run
    result = context.run(func, *args)
  File "/home/omar/.local/lib/python3.10/site-packages/chromadb/telemetry/opentelemetry/__init__.py", line 127, in wrapper
    return f(*args, **kwargs)
  File "/home/omar/.local/lib/python3.10/site-packages/chromadb/auth/fastapi.py", line 241, in wrapped
    return f(*args, **kwargs)
  File "/home/omar/.local/lib/python3.10/site-packages/chromadb/server/fastapi/__init__.py", line 415, in create_collection
    return self._api.create_collection(
  File "/home/omar/.local/lib/python3.10/site-packages/chromadb/telemetry/opentelemetry/__init__.py", line 127, in wrapper
    return f(*args, **kwargs)
  File "/home/omar/.local/lib/python3.10/site-packages/chromadb/api/segment.py", line 167, in create_collection
    coll, created = self._sysdb.create_collection(
  File "/home/omar/.local/lib/python3.10/site-packages/chromadb/telemetry/opentelemetry/__init__.py", line 127, in wrapper
    return f(*args, **kwargs)
  File "/home/omar/.local/lib/python3.10/site-packages/chromadb/db/mixins/sysdb.py", line 225, in create_collection
    raise UniqueConstraintError(f"Collection {name} already exists")
chromadb.db.base.UniqueConstraintError: Collection test-collection already exists
[32mINFO[0m:     [07-04-2024 14:59:10] 127.0.0.1:38088 - "POST /api/v1/collections?tenant=default_tenant&database=default_database HTTP/1.1" 500
[32mINFO[0m:     [07-04-2024 15:07:24] Shutting down
[32mINFO[0m:     [07-04-2024 15:07:24] Waiting for application shutdown.
[36mDEBUG[0m:    [07-04-2024 15:07:24] Stopping component System
[36mDEBUG[0m:    [07-04-2024 15:07:24] Stopping component SegmentAPI
[36mDEBUG[0m:    [07-04-2024 15:07:24] Stopping component PersistentLocalHnswSegment
[36mDEBUG[0m:    [07-04-2024 15:07:24] Stopping component LocalSegmentManager
[36mDEBUG[0m:    [07-04-2024 15:07:24] Stopping component Posthog
[36mDEBUG[0m:    [07-04-2024 15:07:24] Stopping component QuotaEnforcer
[36mDEBUG[0m:    [07-04-2024 15:07:24] Stopping component SqliteDB
[36mDEBUG[0m:    [07-04-2024 15:07:24] Stopping component SimpleAssignmentPolicy
[36mDEBUG[0m:    [07-04-2024 15:07:24] Stopping component OpenTelemetryClient
[32mINFO[0m:     [07-04-2024 15:07:24] Application shutdown complete.
[32mINFO[0m:     [07-04-2024 15:07:24] Finished server process [[36m18621[0m]
[33mWARNING[0m:  [07-04-2024 15:07:47] chroma_server_nofile is set to 65535, but this is less than current soft limit of 1048576. chroma_server_nofile will not be set.
[32mINFO[0m:     [07-04-2024 15:07:47] Anonymized telemetry enabled. See                     https://docs.trychroma.com/telemetry for more information.
[36mDEBUG[0m:    [07-04-2024 15:07:47] Starting component System
[36mDEBUG[0m:    [07-04-2024 15:07:47] Starting component OpenTelemetryClient
[36mDEBUG[0m:    [07-04-2024 15:07:47] Starting component SimpleAssignmentPolicy
[36mDEBUG[0m:    [07-04-2024 15:07:47] Starting component SqliteDB
[36mDEBUG[0m:    [07-04-2024 15:07:47] Starting component QuotaEnforcer
[36mDEBUG[0m:    [07-04-2024 15:07:47] Starting component Posthog
[36mDEBUG[0m:    [07-04-2024 15:07:47] Starting component LocalSegmentManager
[36mDEBUG[0m:    [07-04-2024 15:07:47] Starting component SegmentAPI
[32mINFO[0m:     [07-04-2024 15:07:47] Started server process [[36m30932[0m]
[32mINFO[0m:     [07-04-2024 15:07:47] Waiting for application startup.
[32mINFO[0m:     [07-04-2024 15:07:47] Application startup complete.
[32mINFO[0m:     [07-04-2024 15:07:47] Uvicorn running on [1mhttp://localhost:8000[0m (Press CTRL+C to quit)
[32mINFO[0m:     [07-04-2024 15:08:09] 127.0.0.1:39702 - "GET /api/v1/tenants/default_tenant HTTP/1.1" 200
[32mINFO[0m:     [07-04-2024 15:08:09] 127.0.0.1:39702 - "GET /api/v1/databases/default_database?tenant=default_tenant HTTP/1.1" 200
[32mINFO[0m:     [07-04-2024 15:08:09] 127.0.0.1:39718 - "GET /api/v1 HTTP/1.1" 200
[32mINFO[0m:     [07-04-2024 15:08:27] 127.0.0.1:39244 - "GET /api/v1/tenants/default_tenant HTTP/1.1" 200
[32mINFO[0m:     [07-04-2024 15:08:27] 127.0.0.1:39244 - "GET /api/v1/databases/default_database?tenant=default_tenant HTTP/1.1" 200
[32mINFO[0m:     [07-04-2024 15:08:27] 127.0.0.1:39250 - "GET /api/v1 HTTP/1.1" 200
[32mINFO[0m:     [07-04-2024 15:11:19] 127.0.0.1:42416 - "GET /api/v1/tenants/default_tenant HTTP/1.1" 200
[32mINFO[0m:     [07-04-2024 15:11:19] 127.0.0.1:42416 - "GET /api/v1/databases/default_database?tenant=default_tenant HTTP/1.1" 200
[32mINFO[0m:     [07-04-2024 15:11:19] 127.0.0.1:42420 - "GET /api/v1 HTTP/1.1" 200
[32mINFO[0m:     [07-04-2024 15:11:19] 127.0.0.1:42420 - "POST /api/v1/collections?tenant=default_tenant&database=default_database HTTP/1.1" 200
[32mINFO[0m:     [07-04-2024 15:12:52] 127.0.0.1:44960 - "GET /api/v1/tenants/default_tenant HTTP/1.1" 200
[32mINFO[0m:     [07-04-2024 15:12:52] 127.0.0.1:44960 - "GET /api/v1/databases/default_database?tenant=default_tenant HTTP/1.1" 200
[32mINFO[0m:     [07-04-2024 15:12:52] 127.0.0.1:44974 - "GET /api/v1 HTTP/1.1" 200
[32mINFO[0m:     [07-04-2024 15:12:52] 127.0.0.1:44974 - "POST /api/v1/collections?tenant=default_tenant&database=default_database HTTP/1.1" 200
[32mINFO[0m:     [07-04-2024 15:33:13] Shutting down
[32mINFO[0m:     [07-04-2024 15:33:14] Waiting for application shutdown.
[36mDEBUG[0m:    [07-04-2024 15:33:14] Stopping component System
[36mDEBUG[0m:    [07-04-2024 15:33:14] Stopping component SegmentAPI
[36mDEBUG[0m:    [07-04-2024 15:33:14] Stopping component LocalSegmentManager
[36mDEBUG[0m:    [07-04-2024 15:33:14] Stopping component Posthog
[36mDEBUG[0m:    [07-04-2024 15:33:14] Stopping component QuotaEnforcer
[36mDEBUG[0m:    [07-04-2024 15:33:14] Stopping component SqliteDB
[36mDEBUG[0m:    [07-04-2024 15:33:14] Stopping component SimpleAssignmentPolicy
[36mDEBUG[0m:    [07-04-2024 15:33:14] Stopping component OpenTelemetryClient
[32mINFO[0m:     [07-04-2024 15:33:14] Application shutdown complete.
[32mINFO[0m:     [07-04-2024 15:33:14] Finished server process [[36m30932[0m]
[33mWARNING[0m:  [07-04-2024 15:35:48] chroma_server_nofile is set to 65535, but this is less than current soft limit of 1048576. chroma_server_nofile will not be set.
[32mINFO[0m:     [07-04-2024 15:35:48] Anonymized telemetry enabled. See                     https://docs.trychroma.com/telemetry for more information.
[36mDEBUG[0m:    [07-04-2024 15:35:48] Starting component System
[36mDEBUG[0m:    [07-04-2024 15:35:48] Starting component OpenTelemetryClient
[36mDEBUG[0m:    [07-04-2024 15:35:48] Starting component SimpleAssignmentPolicy
[36mDEBUG[0m:    [07-04-2024 15:35:48] Starting component SqliteDB
[36mDEBUG[0m:    [07-04-2024 15:35:48] Starting component QuotaEnforcer
[36mDEBUG[0m:    [07-04-2024 15:35:48] Starting component Posthog
[36mDEBUG[0m:    [07-04-2024 15:35:48] Starting component LocalSegmentManager
[36mDEBUG[0m:    [07-04-2024 15:35:48] Starting component SegmentAPI
[32mINFO[0m:     [07-04-2024 15:35:48] Started server process [[36m34252[0m]
[32mINFO[0m:     [07-04-2024 15:35:48] Waiting for application startup.
[32mINFO[0m:     [07-04-2024 15:35:48] Application startup complete.
[32mINFO[0m:     [07-04-2024 15:35:48] Uvicorn running on [1mhttp://localhost:8000[0m (Press CTRL+C to quit)
[32mINFO[0m:     [07-04-2024 15:36:42] 127.0.0.1:44348 - "POST /api/v1/collections?tenant=default_tenant&database=default_database HTTP/1.1" 200
[31mERROR[0m:    [07-04-2024 15:36:54] Collection my_collection already exists
Traceback (most recent call last):
  File "/home/omar/.local/lib/python3.10/site-packages/anyio/streams/memory.py", line 98, in receive
    return self.receive_nowait()
  File "/home/omar/.local/lib/python3.10/site-packages/anyio/streams/memory.py", line 93, in receive_nowait
    raise WouldBlock
anyio.WouldBlock

During handling of the above exception, another exception occurred:

Traceback (most recent call last):
  File "/home/omar/.local/lib/python3.10/site-packages/starlette/middleware/base.py", line 159, in call_next
    message = await recv_stream.receive()
  File "/home/omar/.local/lib/python3.10/site-packages/anyio/streams/memory.py", line 118, in receive
    raise EndOfStream
anyio.EndOfStream

During handling of the above exception, another exception occurred:

Traceback (most recent call last):
  File "/home/omar/.local/lib/python3.10/site-packages/chromadb/server/fastapi/__init__.py", line 82, in catch_exceptions_middleware
    return await call_next(request)
  File "/home/omar/.local/lib/python3.10/site-packages/starlette/middleware/base.py", line 165, in call_next
    raise app_exc
  File "/home/omar/.local/lib/python3.10/site-packages/starlette/middleware/base.py", line 151, in coro
    await self.app(scope, receive_or_disconnect, send_no_error)
  File "/home/omar/.local/lib/python3.10/site-packages/starlette/middleware/base.py", line 191, in __call__
    response = await self.dispatch_func(request, call_next)
  File "/home/omar/.local/lib/python3.10/site-packages/chromadb/server/fastapi/__init__.py", line 96, in check_http_version_middleware
    return await call_next(request)
  File "/home/omar/.local/lib/python3.10/site-packages/starlette/middleware/base.py", line 165, in call_next
    raise app_exc
  File "/home/omar/.local/lib/python3.10/site-packages/starlette/middleware/base.py", line 151, in coro
    await self.app(scope, receive_or_disconnect, send_no_error)
  File "/home/omar/.local/lib/python3.10/site-packages/starlette/middleware/exceptions.py", line 65, in __call__
    await wrap_app_handling_exceptions(self.app, conn)(scope, receive, send)
  File "/home/omar/.local/lib/python3.10/site-packages/starlette/_exception_handler.py", line 64, in wrapped_app
    raise exc
  File "/home/omar/.local/lib/python3.10/site-packages/starlette/_exception_handler.py", line 53, in wrapped_app
    await app(scope, receive, sender)
  File "/home/omar/.local/lib/python3.10/site-packages/starlette/routing.py", line 756, in __call__
    await self.middleware_stack(scope, receive, send)
  File "/home/omar/.local/lib/python3.10/site-packages/starlette/routing.py", line 776, in app
    await route.handle(scope, receive, send)
  File "/home/omar/.local/lib/python3.10/site-packages/starlette/routing.py", line 297, in handle
    await self.app(scope, receive, send)
  File "/home/omar/.local/lib/python3.10/site-packages/starlette/routing.py", line 77, in app
    await wrap_app_handling_exceptions(app, request)(scope, receive, send)
  File "/home/omar/.local/lib/python3.10/site-packages/starlette/_exception_handler.py", line 64, in wrapped_app
    raise exc
  File "/home/omar/.local/lib/python3.10/site-packages/starlette/_exception_handler.py", line 53, in wrapped_app
    await app(scope, receive, sender)
  File "/home/omar/.local/lib/python3.10/site-packages/starlette/routing.py", line 72, in app
    response = await func(request)
  File "/home/omar/.local/lib/python3.10/site-packages/fastapi/routing.py", line 278, in app
    raw_response = await run_endpoint_function(
  File "/home/omar/.local/lib/python3.10/site-packages/fastapi/routing.py", line 193, in run_endpoint_function
    return await run_in_threadpool(dependant.call, **values)
  File "/home/omar/.local/lib/python3.10/site-packages/starlette/concurrency.py", line 42, in run_in_threadpool
    return await anyio.to_thread.run_sync(func, *args)
  File "/home/omar/.local/lib/python3.10/site-packages/anyio/to_thread.py", line 33, in run_sync
    return await get_asynclib().run_sync_in_worker_thread(
  File "/home/omar/.local/lib/python3.10/site-packages/anyio/_backends/_asyncio.py", line 877, in run_sync_in_worker_thread
    return await future
  File "/home/omar/.local/lib/python3.10/site-packages/anyio/_backends/_asyncio.py", line 807, in run
    result = context.run(func, *args)
  File "/home/omar/.local/lib/python3.10/site-packages/chromadb/telemetry/opentelemetry/__init__.py", line 127, in wrapper
    return f(*args, **kwargs)
  File "/home/omar/.local/lib/python3.10/site-packages/chromadb/auth/fastapi.py", line 241, in wrapped
    return f(*args, **kwargs)
  File "/home/omar/.local/lib/python3.10/site-packages/chromadb/server/fastapi/__init__.py", line 415, in create_collection
    return self._api.create_collection(
  File "/home/omar/.local/lib/python3.10/site-packages/chromadb/telemetry/opentelemetry/__init__.py", line 127, in wrapper
    return f(*args, **kwargs)
  File "/home/omar/.local/lib/python3.10/site-packages/chromadb/api/segment.py", line 167, in create_collection
    coll, created = self._sysdb.create_collection(
  File "/home/omar/.local/lib/python3.10/site-packages/chromadb/telemetry/opentelemetry/__init__.py", line 127, in wrapper
    return f(*args, **kwargs)
  File "/home/omar/.local/lib/python3.10/site-packages/chromadb/db/mixins/sysdb.py", line 225, in create_collection
    raise UniqueConstraintError(f"Collection {name} already exists")
chromadb.db.base.UniqueConstraintError: Collection my_collection already exists
[32mINFO[0m:     [07-04-2024 15:36:54] 127.0.0.1:47500 - "POST /api/v1/collections?tenant=default_tenant&database=default_database HTTP/1.1" 500
[32mINFO[0m:     [07-04-2024 15:37:43] 127.0.0.1:34204 - "POST /api/v1/collections?tenant=default_tenant&database=default_database HTTP/1.1" 422
[32mINFO[0m:     [07-04-2024 15:37:44] 127.0.0.1:34208 - "POST /api/v1/collections?tenant=default_tenant&database=default_database HTTP/1.1" 422
